Workbook

Sheet 2026-01
C1: Payroll ID | E1: UNIVERSITY OF ALABAMA IN HUNTSVILLE
E2: Biweekly Labor Report
C3: 2026-01
C6: Name: | I6: A#: | M6: Position #: | Q6: Title:
C8: Department: | E8: Earth System Science Center | I8: Pay Period: | K8: 46001 | M8: to | N8: 46014 | Q8: FTE: | R8: 1
C10: Home Labor: | E10: 740001 | I10: Check Date: | L10: =N8+10 -> 46024
C14: 6 digit Org/Index | D14: Account Code | E14: % Distribution | G14: COMMENTS
C27: Total Labor | E27: =SUM(E15:E26) -> 0 | G27: =IF(E27=100%,"","ERROR: TOTAL LABOR MUST BE 100%!!!") -> ERROR: TOTAL LABOR MUST BE 100%!!!
C28: I certify that the distribution of labor above represents the actual work performed during this reporting period.
C30: Employee Signature | Q30: Date
C32: Supervisor Signature | Q32: Date
C34: Budget Unit Head Signature | Q34: Date

Sheet 2026-02
C1: Payroll ID | E1: UNIVERSITY OF ALABAMA IN HUNTSVILLE
E2: Biweekly Labor Report
C3: 2026-02
C6: Name: | E6: ='2026-01'!E6:H6 -> 0 | I6: A#: | J6: ='2026-01'!J6:L6 -> 0 | M6: Position #: | O6: ='2026-01'!O6:P6 -> 0 | Q6: Title: | R6: ='2026-01'!R6:T6 -> 0
C8: Department: | E8: ='2026-01'!E8:H8 -> Earth System Science Center | I8: Pay Period: | K8: ='2026-01'!K8:L8+14 -> 46015 | M8: to | N8: ='2026-01'!N8:O8+14 -> 46028 | Q8: FTE: | R8: ='2026-01'!R8 -> 1
C10: Home Labor: | E10: ='2026-01'!E10:H10 -> 740001 | I10: Check Date: | L10: =N8+10 -> 46038
C14: 6 digit Org/Index | D14: Account Code | E14: % Distribution | G14: COMMENTS
C15: =IF('2026-01'!C15=0,"",'2026-01'!C15) | D15: =IF('2026-01'!D15=0,"",'2026-01'!D15) | E15: =IF('2026-01'!E15=0,"",'2026-01'!E15)
C16: =IF('2026-01'!C16=0,"",'2026-01'!C16) | D16: =IF('2026-01'!D16=0,"",'2026-01'!D16) | E16: =IF('2026-01'!E16=0,"",'2026-01'!E16)
C17: =IF('2026-01'!C17=0,"",'2026-01'!C17) | D17: =IF('2026-01'!D17=0,"",'2026-01'!D17) | E17: =IF('2026-01'!E17=0,"",'2026-01'!E17)
C18: =IF('2026-01'!C18=0,"",'2026-01'!C18) | D18: =IF('2026-01'!D18=0,"",'2026-01'!D18) | E18: =IF('2026-01'!E18=0,"",'2026-01'!E18)
C19: =IF('2026-01'!C19=0,"",'2026-01'!C19) | D19: =IF('2026-01'!D19=0,"",'2026-01'!D19) | E19: =IF('2026-01'!E19=0,"",'2026-01'!E19)
C20: =IF('2026-01'!C20=0,"",'2026-01'!C20) | D20: =IF('2026-01'!D20=0,"",'2026-01'!D20) | E20: =IF('2026-01'!E20=0,"",'2026-01'!E20)
C21: =IF('2026-01'!C21=0,"",'2026-01'!C21) | D21: =IF('2026-01'!D21=0,"",'2026-01'!D21) | E21: =IF('2026-01'!E21=0,"",'2026-01'!E21)
C22: =IF('2026-01'!C22=0,"",'2026-01'!C22) | D22: =IF('2026-01'!D22=0,"",'2026-01'!D22) | E22: =IF('2026-01'!E22=0,"",'2026-01'!E22)
C23: =IF('2026-01'!C23=0,"",'2026-01'!C23) | D23: =IF('2026-01'!D23=0,"",'2026-01'!D23) | E23: =IF('2026-01'!E23=0,"",'2026-01'!E23)
C24: =IF('2026-01'!C24=0,"",'2026-01'!C24) | D24: =IF('2026-01'!D24=0,"",'2026-01'!D24) | E24: =IF('2026-01'!E24=0,"",'2026-01'!E24)
C25: =IF('2026-01'!C25=0,"",'2026-01'!C25) | D25: =IF('2026-01'!D25=0,"",'2026-01'!D25) | E25: =IF('2026-01'!E25=0,"",'2026-01'!E25)
C26: =IF('2026-01'!C26=0,"",'2026-01'!C26) | D26: =IF('2026-01'!D26=0,"",'2026-01'!D26) | E26: =IF('2026-01'!E26=0,"",'2026-01'!E26)
C27: Total Labor | E27: =SUM(E15:E26) -> 0 | G27: =IF(E27=100%,"","ERROR: TOTAL LABOR MUST BE 100%!!!") -> ERROR: TOTAL LABOR MUST BE 100%!!!
C28: I certify that the distribution of labor above represents the actual work performed during this reporting period.
C30: Employee Signature | Q30: Date
C32: Supervisor Signature | Q32: Date
C34: Budget Unit Head Signature | Q34: Date

Sheet 2026-03
C1: Payroll ID | E1: UNIVERSITY OF ALABAMA IN HUNTSVILLE
E2: Biweekly Labor Report
C3: 2026-03
C6: Name: | E6: ='2026-02'!E6:H6 -> 0 | I6: A#: | J6: ='2026-02'!J6:L6 -> 0 | M6: Position #: | O6: ='2026-02'!O6:P6 -> 0 | Q6: Title: | R6: ='2026-02'!R6:T6 -> 0
C8: Department: | E8: ='2026-02'!E8:H8 -> Earth System Science Center | I8: Pay Period: | K8: ='2026-02'!K8:L8+14 -> 46029 | M8: to | N8: ='2026-02'!N8:O8+14 -> 46042 | Q8: FTE: | R8: ='2026-02'!R8 -> 1
C10: Home Labor: | E10: ='2026-02'!E10:H10 -> 740001 | I10: Check Date: | L10: =N8+10 -> 46052
C14: 6 digit Org/Index | D14: Account Code | E14: % Distribution | G14: COMMENTS
C15: =IF('2026-02'!C15=0,"",'2026-02'!C15) | D15: =IF('2026-02'!D15=0,"",'2026-02'!D15) | E15: =IF('2026-02'!E15=0,"",'2026-02'!E15)
C16: =IF('2026-02'!C16=0,"",'2026-02'!C16) | D16: =IF('2026-02'!D16=0,"",'2026-02'!D16) | E16: =IF('2026-02'!E16=0,"",'2026-02'!E16)
C17: =IF('2026-02'!C17=0,"",'2026-02'!C17) | D17: =IF('2026-02'!D17=0,"",'2026-02'!D17) | E17: =IF('2026-02'!E17=0,"",'2026-02'!E17)
C18: =IF('2026-02'!C18=0,"",'2026-02'!C18) | D18: =IF('2026-02'!D18=0,"",'2026-02'!D18) | E18: =IF('2026-02'!E18=0,"",'2026-02'!E18)
C19: =IF('2026-02'!C19=0,"",'2026-02'!C19) | D19: =IF('2026-02'!D19=0,"",'2026-02'!D19) | E19: =IF('2026-02'!E19=0,"",'2026-02'!E19)
C20: =IF('2026-02'!C20=0,"",'2026-02'!C20) | D20: =IF('2026-02'!D20=0,"",'2026-02'!D20) | E20: =IF('2026-02'!E20=0,"",'2026-02'!E20)
C21: =IF('2026-02'!C21=0,"",'2026-02'!C21) | D21: =IF('2026-02'!D21=0,"",'2026-02'!D21) | E21: =IF('2026-02'!E21=0,"",'2026-02'!E21)
C22: =IF('2026-02'!C22=0,"",'2026-02'!C22) | D22: =IF('2026-02'!D22=0,"",'2026-02'!D22) | E22: =IF('2026-02'!E22=0,"",'2026-02'!E22)
C23: =IF('2026-02'!C23=0,"",'2026-02'!C23) | D23: =IF('2026-02'!D23=0,"",'2026-02'!D23) | E23: =IF('2026-02'!E23=0,"",'2026-02'!E23)
C24: =IF('2026-02'!C24=0,"",'2026-02'!C24) | D24: =IF('2026-02'!D24=0,"",'2026-02'!D24) | E24: =IF('2026-02'!E24=0,"",'2026-02'!E24)
C25: =IF('2026-02'!C25=0,"",'2026-02'!C25) | D25: =IF('2026-02'!D25=0,"",'2026-02'!D25) | E25: =IF('2026-02'!E25=0,"",'2026-02'!E25)
C26: =IF('2026-02'!C26=0,"",'2026-02'!C26) | D26: =IF('2026-02'!D26=0,"",'2026-02'!D26) | E26: =IF('2026-02'!E26=0,"",'2026-02'!E26)
C27: Total Labor | E27: =SUM(E15:E26) -> 0 | G27: =IF(E27=100%,"","ERROR: TOTAL LABOR MUST BE 100%!!!") -> ERROR: TOTAL LABOR MUST BE 100%!!!
C28: I certify that the distribution of labor above represents the actual work performed during this reporting period.
C30: Employee Signature | Q30: Date
C32: Supervisor Signature | Q32: Date
C34: Budget Unit Head Signature | Q34: Date

Sheet 2026-04
C1: Payroll ID | E1: UNIVERSITY OF ALABAMA IN HUNTSVILLE
E2: Biweekly Labor Report
C3: 2026-04
C6: Name: | E6: ='2026-03'!E6:H6 -> 0 | I6: A#: | J6: ='2026-03'!J6:L6 -> 0 | M6: Position #: | O6: ='2026-03'!O6:P6 -> 0 | Q6: Title: | R6: ='2026-03'!R6:T6 -> 0
C8: Department: | E8: ='2026-03'!E8:H8 -> Earth System Science Center | I8: Pay Period: | K8: ='2026-03'!K8:L8+14 -> 46043 | M8: to | N8: ='2026-03'!N8:O8+14 -> 46056 | Q8: FTE: | R8: ='2026-03'!R8 -> 1
C10: Home Labor: | E10: ='2026-03'!E10:H10 -> 740001 | I10: Check Date: | L10: =N8+10 -> 46066
C14: 6 digit Org/Index | D14: Account Code | E14: % Distribution | G14: COMMENTS
C15: =IF('2026-03'!C15=0,"",'2026-03'!C15) | D15: =IF('2026-03'!D15=0,"",'2026-03'!D15) | E15: =IF('2026-03'!E15=0,"",'2026-03'!E15)
C16: =IF('2026-03'!C16=0,"",'2026-03'!C16) | D16: =IF('2026-03'!D16=0,"",'2026-03'!D16) | E16: =IF('2026-03'!E16=0,"",'2026-03'!E16)
C17: =IF('2026-03'!C17=0,"",'2026-03'!C17) | D17: =IF('2026-03'!D17=0,"",'2026-03'!D17) | E17: =IF('2026-03'!E17=0,"",'2026-03'!E17)
C18: =IF('2026-03'!C18=0,"",'2026-03'!C18) | D18: =IF('2026-03'!D18=0,"",'2026-03'!D18) | E18: =IF('2026-03'!E18=0,"",'2026-03'!E18)
C19: =IF('2026-03'!C19=0,"",'2026-03'!C19) | D19: =IF('2026-03'!D19=0,"",'2026-03'!D19) | E19: =IF('2026-03'!E19=0,"",'2026-03'!E19)
C20: =IF('2026-03'!C20=0,"",'2026-03'!C20) | D20: =IF('2026-03'!D20=0,"",'2026-03'!D20) | E20: =IF('2026-03'!E20=0,"",'2026-03'!E20)
C21: =IF('2026-03'!C21=0,"",'2026-03'!C21) | D21: =IF('2026-03'!D21=0,"",'2026-03'!D21) | E21: =IF('2026-03'!E21=0,"",'2026-03'!E21)
C22: =IF('2026-03'!C22=0,"",'2026-03'!C22) | D22: =IF('2026-03'!D22=0,"",'2026-03'!D22) | E22: =IF('2026-03'!E22=0,"",'2026-03'!E22)
C23: =IF('2026-03'!C23=0,"",'2026-03'!C23) | D23: =IF('2026-03'!D23=0,"",'2026-03'!D23) | E23: =IF('2026-03'!E23=0,"",'2026-03'!E23)
C24: =IF('2026-03'!C24=0,"",'2026-03'!C24) | D24: =IF('2026-03'!D24=0,"",'2026-03'!D24) | E24: =IF('2026-03'!E24=0,"",'2026-03'!E24)
C25: =IF('2026-03'!C25=0,"",'2026-03'!C25) | D25: =IF('2026-03'!D25=0,"",'2026-03'!D25) | E25: =IF('2026-03'!E25=0,"",'2026-03'!E25)
C26: =IF('2026-03'!C26=0,"",'2026-03'!C26) | D26: =IF('2026-03'!D26=0,"",'2026-03'!D26) | E26: =IF('2026-03'!E26=0,"",'2026-03'!E26)
C27: Total Labor | E27: =SUM(E15:E26) -> 0 | G27: =IF(E27=100%,"","ERROR: TOTAL LABOR MUST BE 100%!!!") -> ERROR: TOTAL LABOR MUST BE 100%!!!
C28: I certify that the distribution of labor above represents the actual work performed during this reporting period.
C30: Employee Signature | Q30: Date
C32: Supervisor Signature | Q32: Date
C34: Budget Unit Head Signature | Q34: Date

Sheet 2026-05
C1: Payroll ID | E1: UNIVERSITY OF ALABAMA IN HUNTSVILLE
E2: Biweekly Labor Report
C3: 2026-05
C6: Name: | E6: ='2026-04'!E6:H6 -> 0 | I6: A#: | J6: ='2026-04'!J6:L6 -> 0 | M6: Position #: | O6: ='2026-04'!O6:P6 -> 0 | Q6: Title: | R6: ='2026-04'!R6:T6 -> 0
C8: Department: | E8: ='2026-04'!E8:H8 -> Earth System Science Center | I8: Pay Period: | K8: ='2026-04'!K8:L8+14 -> 46057 | M8: to | N8: ='2026-04'!N8:O8+14 -> 46070 | Q8: FTE: | R8: ='2026-04'!R8 -> 1
C10: Home Labor: | E10: ='2026-04'!E10:H10 -> 740001 | I10: Check Date: | L10: =N8+10 -> 46080
C14: 6 digit Org/Index | D14: Account Code | E14: % Distribution | G14: COMMENTS
C15: =IF('2026-04'!C15=0,"",'2026-04'!C15) | D15: =IF('2026-04'!D15=0,"",'2026-04'!D15) | E15: =IF('2026-04'!E15=0,"",'2026-04'!E15)
C16: =IF('2026-04'!C16=0,"",'2026-04'!C16) | D16: =IF('2026-04'!D16=0,"",'2026-04'!D16) | E16: =IF('2026-04'!E16=0,"",'2026-04'!E16)
C17: =IF('2026-04'!C17=0,"",'2026-04'!C17) | D17: =IF('2026-04'!D17=0,"",'2026-04'!D17) | E17: =IF('2026-04'!E17=0,"",'2026-04'!E17)
C18: =IF('2026-04'!C18=0,"",'2026-04'!C18) | D18: =IF('2026-04'!D18=0,"",'2026-04'!D18) | E18: =IF('2026-04'!E18=0,"",'2026-04'!E18)
C19: =IF('2026-04'!C19=0,"",'2026-04'!C19) | D19: =IF('2026-04'!D19=0,"",'2026-04'!D19) | E19: =IF('2026-04'!E19=0,"",'2026-04'!E19)
C20: =IF('2026-04'!C20=0,"",'2026-04'!C20) | D20: =IF('2026-04'!D20=0,"",'2026-04'!D20) | E20: =IF('2026-04'!E20=0,"",'2026-04'!E20)
C21: =IF('2026-04'!C21=0,"",'2026-04'!C21) | D21: =IF('2026-04'!D21=0,"",'2026-04'!D21) | E21: =IF('2026-04'!E21=0,"",'2026-04'!E21)
C22: =IF('2026-04'!C22=0,"",'2026-04'!C22) | D22: =IF('2026-04'!D22=0,"",'2026-04'!D22) | E22: =IF('2026-04'!E22=0,"",'2026-04'!E22)
C23: =IF('2026-04'!C23=0,"",'2026-04'!C23) | D23: =IF('2026-04'!D23=0,"",'2026-04'!D23) | E23: =IF('2026-04'!E23=0,"",'2026-04'!E23)
C24: =IF('2026-04'!C24=0,"",'2026-04'!C24) | D24: =IF('2026-04'!D24=0,"",'2026-04'!D24) | E24: =IF('2026-04'!E24=0,"",'2026-04'!E24)
C25: =IF('2026-04'!C25=0,"",'2026-04'!C25) | D25: =IF('2026-04'!D25=0,"",'2026-04'!D25) | E25: =IF('2026-04'!E25=0,"",'2026-04'!E25)
C26: =IF('2026-04'!C26=0,"",'2026-04'!C26) | D26: =IF('2026-04'!D26=0,"",'2026-04'!D26) | E26: =IF('2026-04'!E26=0,"",'2026-04'!E26)
C27: Total Labor | E27: =SUM(E15:E26) -> 0 | G27: =IF(E27=100%,"","ERROR: TOTAL LABOR MUST BE 100%!!!") -> ERROR: TOTAL LABOR MUST BE 100%!!!
C28: I certify that the distribution of labor above represents the actual work performed during this reporting period.
C30: Employee Signature | Q30: Date
C32: Supervisor Signature | Q32: Date
C34: Budget Unit Head Signature | Q34: Date

Sheet 2026-06
C1: Payroll ID | E1: UNIVERSITY OF ALABAMA IN HUNTSVILLE
E2: Biweekly Labor Report
C3: 2026-06
C6: Name: | E6: ='2026-05'!E6:H6 -> 0 | I6: A#: | J6: ='2026-05'!J6:L6 -> 0 | M6: Position #: | O6: ='2026-05'!O6:P6 -> 0 | Q6: Title: | R6: ='2026-05'!R6:T6 -> 0
C8: Department: | E8: ='2026-05'!E8:H8 -> Earth System Science Center | I8: Pay Period: | K8: ='2026-05'!K8:L8+14 -> 46071 | M8: to | N8: ='2026-05'!N8:O8+14 -> 46084 | Q8: FTE: | R8: ='2026-05'!R8 -> 1
C10: Home Labor: | E10: ='2026-05'!E10:H10 -> 740001 | I10: Check Date: | L10: =N8+10 -> 46094
C14: 6 digit Org/Index | D14: Account Code | E14: % Distribution | G14: COMMENTS
C15: =IF('2026-05'!C15=0,"",'2026-05'!C15) | D15: =IF('2026-05'!D15=0,"",'2026-05'!D15) | E15: =IF('2026-05'!E15=0,"",'2026-05'!E15)
C16: =IF('2026-05'!C16=0,"",'2026-05'!C16) | D16: =IF('2026-05'!D16=0,"",'2026-05'!D16) | E16: =IF('2026-05'!E16=0,"",'2026-05'!E16)
C17: =IF('2026-05'!C17=0,"",'2026-05'!C17) | D17: =IF('2026-05'!D17=0,"",'2026-05'!D17) | E17: =IF('2026-05'!E17=0,"",'2026-05'!E17)
C18: =IF('2026-05'!C18=0,"",'2026-05'!C18) | D18: =IF('2026-05'!D18=0,"",'2026-05'!D18) | E18: =IF('2026-05'!E18=0,"",'2026-05'!E18)
C19: =IF('2026-05'!C19=0,"",'2026-05'!C19) | D19: =IF('2026-05'!D19=0,"",'2026-05'!D19) | E19: =IF('2026-05'!E19=0,"",'2026-05'!E19)
C20: =IF('2026-05'!C20=0,"",'2026-05'!C20) | D20: =IF('2026-05'!D20=0,"",'2026-05'!D20) | E20: =IF('2026-05'!E20=0,"",'2026-05'!E20)
C21: =IF('2026-05'!C21=0,"",'2026-05'!C21) | D21: =IF('2026-05'!D21=0,"",'2026-05'!D21) | E21: =IF('2026-05'!E21=0,"",'2026-05'!E21)
C22: =IF('2026-05'!C22=0,"",'2026-05'!C22) | D22: =IF('2026-05'!D22=0,"",'2026-05'!D22) | E22: =IF('2026-05'!E22=0,"",'2026-05'!E22)
C23: =IF('2026-05'!C23=0,"",'2026-05'!C23) | D23: =IF('2026-05'!D23=0,"",'2026-05'!D23) | E23: =IF('2026-05'!E23=0,"",'2026-05'!E23)
C24: =IF('2026-05'!C24=0,"",'2026-05'!C24) | D24: =IF('2026-05'!D24=0,"",'2026-05'!D24) | E24: =IF('2026-05'!E24=0,"",'2026-05'!E24)
C25: =IF('2026-05'!C25=0,"",'2026-05'!C25) | D25: =IF('2026-05'!D25=0,"",'2026-05'!D25) | E25: =IF('2026-05'!E25=0,"",'2026-05'!E25)
C26: =IF('2026-05'!C26=0,"",'2026-05'!C26) | D26: =IF('2026-05'!D26=0,"",'2026-05'!D26) | E26: =IF('2026-05'!E26=0,"",'2026-05'!E26)
C27: Total Labor | E27: =SUM(E15:E26) -> 0 | G27: =IF(E27=100%,"","ERROR: TOTAL LABOR MUST BE 100%!!!") -> ERROR: TOTAL LABOR MUST BE 100%!!!
C28: I certify that the distribution of labor above represents the actual work performed during this reporting period.
C30: Employee Signature | Q30: Date
C32: Supervisor Signature | Q32: Date
C34: Budget Unit Head Signature | Q34: Date

Sheet 2026-07
C1: Payroll ID | E1: UNIVERSITY OF ALABAMA IN HUNTSVILLE
E2: Biweekly Labor Report
C3: 2026-07
C6: Name: | E6: ='2026-06'!E6:H6 -> 0 | I6: A#: | J6: ='2026-06'!J6:L6 -> 0 | M6: Position #: | O6: ='2026-06'!O6:P6 -> 0 | Q6: Title: | R6: ='2026-06'!R6:T6 -> 0
C8: Department: | E8: ='2026-06'!E8:H8 -> Earth System Science Center | I8: Pay Period: | K8: ='2026-06'!K8:L8+14 -> 46085 | M8: to | N8: ='2026-06'!N8:O8+14 -> 46098 | Q8: FTE: | R8: ='2026-06'!R8 -> 1
C10: Home Labor: | E10: ='2026-06'!E10:H10 -> 740001 | I10: Check Date: | L10: =N8+10 -> 46108
C14: 6 digit Org/Index | D14: Account Code | E14: % Distribution | G14: COMMENTS
C15: =IF('2026-06'!C15=0,"",'2026-06'!C15) | D15: =IF('2026-06'!D15=0,"",'2026-06'!D15) | E15: =IF('2026-06'!E15=0,"",'2026-06'!E15)
C16: =IF('2026-06'!C16=0,"",'2026-06'!C16) | D16: =IF('2026-06'!D16=0,"",'2026-06'!D16) | E16: =IF('2026-06'!E16=0,"",'2026-06'!E16)
C17: =IF('2026-06'!C17=0,"",'2026-06'!C17) | D17: =IF('2026-06'!D17=0,"",'2026-06'!D17) | E17: =IF('2026-06'!E17=0,"",'2026-06'!E17)
C18: =IF('2026-06'!C18=0,"",'2026-06'!C18) | D18: =IF('2026-06'!D18=0,"",'2026-06'!D18) | E18: =IF('2026-06'!E18=0,"",'2026-06'!E18)
C19: =IF('2026-06'!C19=0,"",'2026-06'!C19) | D19: =IF('2026-06'!D19=0,"",'2026-06'!D19) | E19: =IF('2026-06'!E19=0,"",'2026-06'!E19)
C20: =IF('2026-06'!C20=0,"",'2026-06'!C20) | D20: =IF('2026-06'!D20=0,"",'2026-06'!D20) | E20: =IF('2026-06'!E20=0,"",'2026-06'!E20)
C21: =IF('2026-06'!C21=0,"",'2026-06'!C21) | D21: =IF('2026-06'!D21=0,"",'2026-06'!D21) | E21: =IF('2026-06'!E21=0,"",'2026-06'!E21)
C22: =IF('2026-06'!C22=0,"",'2026-06'!C22) | D22: =IF('2026-06'!D22=0,"",'2026-06'!D22) | E22: =IF('2026-06'!E22=0,"",'2026-06'!E22)
C23: =IF('2026-06'!C23=0,"",'2026-06'!C23) | D23: =IF('2026-06'!D23=0,"",'2026-06'!D23) | E23: =IF('2026-06'!E23=0,"",'2026-06'!E23)
C24: =IF('2026-06'!C24=0,"",'2026-06'!C24) | D24: =IF('2026-06'!D24=0,"",'2026-06'!D24) | E24: =IF('2026-06'!E24=0,"",'2026-06'!E24)
C25: =IF('2026-06'!C25=0,"",'2026-06'!C25) | D25: =IF('2026-06'!D25=0,"",'2026-06'!D25) | E25: =IF('2026-06'!E25=0,"",'2026-06'!E25)
C26: =IF('2026-06'!C26=0,"",'2026-06'!C26) | D26: =IF('2026-06'!D26=0,"",'2026-06'!D26) | E26: =IF('2026-06'!E26=0,"",'2026-06'!E26)
C27: Total Labor | E27: =SUM(E15:E26) -> 0 | G27: =IF(E27=100%,"","ERROR: TOTAL LABOR MUST BE 100%!!!") -> ERROR: TOTAL LABOR MUST BE 100%!!!
C28: I certify that the distribution of labor above represents the actual work performed during this reporting period.
C30: Employee Signature | Q30: Date
C32: Supervisor Signature | Q32: Date
C34: Budget Unit Head Signature | Q34: Date

Sheet 2026-08
C1: Payroll ID | E1: UNIVERSITY OF ALABAMA IN HUNTSVILLE
E2: Biweekly Labor Report
C3: 2026-08
C6: Name: | E6: ='2026-07'!E6:H6 -> 0 | I6: A#: | J6: ='2026-07'!J6:L6 -> 0 | M6: Position #: | O6: ='2026-07'!O6:P6 -> 0 | Q6: Title: | R6: ='2026-07'!R6:T6 -> 0
C8: Department: | E8: ='2026-07'!E8:H8 -> Earth System Science Center | I8: Pay Period: | K8: ='2026-07'!K8:L8+14 -> 46099 | M8: to | N8: ='2026-07'!N8:O8+14 -> 46112 | Q8: FTE: | R8: ='2026-07'!R8 -> 1
C10: Home Labor: | E10: ='2026-07'!E10:H10 -> 740001 | I10: Check Date: | L10: =N8+10 -> 46122
C14: 6 digit Org/Index | D14: Account Code | E14: % Distribution | G14: COMMENTS
C15: =IF('2026-07'!C15=0,"",'2026-07'!C15) | D15: =IF('2026-07'!D15=0,"",'2026-07'!D15) | E15: =IF('2026-07'!E15=0,"",'2026-07'!E15)
C16: =IF('2026-07'!C16=0,"",'2026-07'!C16) | D16: =IF('2026-07'!D16=0,"",'2026-07'!D16) | E16: =IF('2026-07'!E16=0,"",'2026-07'!E16)
C17: =IF('2026-07'!C17=0,"",'2026-07'!C17) | D17: =IF('2026-07'!D17=0,"",'2026-07'!D17) | E17: =IF('2026-07'!E17=0,"",'2026-07'!E17)
C18: =IF('2026-07'!C18=0,"",'2026-07'!C18) | D18: =IF('2026-07'!D18=0,"",'2026-07'!D18) | E18: =IF('2026-07'!E18=0,"",'2026-07'!E18)
C19: =IF('2026-07'!C19=0,"",'2026-07'!C19) | D19: =IF('2026-07'!D19=0,"",'2026-07'!D19) | E19: =IF('2026-07'!E19=0,"",'2026-07'!E19)
C20: =IF('2026-07'!C20=0,"",'2026-07'!C20) | D20: =IF('2026-07'!D20=0,"",'2026-07'!D20) | E20: =IF('2026-07'!E20=0,"",'2026-07'!E20)
C21: =IF('2026-07'!C21=0,"",'2026-07'!C21) | D21: =IF('2026-07'!D21=0,"",'2026-07'!D21) | E21: =IF('2026-07'!E21=0,"",'2026-07'!E21)
C22: =IF('2026-07'!C22=0,"",'2026-07'!C22) | D22: =IF('2026-07'!D22=0,"",'2026-07'!D22) | E22: =IF('2026-07'!E22=0,"",'2026-07'!E22)
C23: =IF('2026-07'!C23=0,"",'2026-07'!C23) | D23: =IF('2026-07'!D23=0,"",'2026-07'!D23) | E23: =IF('2026-07'!E23=0,"",'2026-07'!E23)
C24: =IF('2026-07'!C24=0,"",'2026-07'!C24) | D24: =IF('2026-07'!D24=0,"",'2026-07'!D24) | E24: =IF('2026-07'!E24=0,"",'2026-07'!E24)
C25: =IF('2026-07'!C25=0,"",'2026-07'!C25) | D25: =IF('2026-07'!D25=0,"",'2026-07'!D25) | E25: =IF('2026-07'!E25=0,"",'2026-07'!E25)
C26: =IF('2026-07'!C26=0,"",'2026-07'!C26) | D26: =IF('2026-07'!D26=0,"",'2026-07'!D26) | E26: =IF('2026-07'!E26=0,"",'2026-07'!E26)
C27: Total Labor | E27: =SUM(E15:E26) -> 0 | G27: =IF(E27=100%,"","ERROR: TOTAL LABOR MUST BE 100%!!!") -> ERROR: TOTAL LABOR MUST BE 100%!!!
C28: I certify that the distribution of labor above represents the actual work performed during this reporting period.
C30: Employee Signature | Q30: Date
C32: Supervisor Signature | Q32: Date
C34: Budget Unit Head Signature | Q34: Date

Sheet 2026-09
C1: Payroll ID | E1: UNIVERSITY OF ALABAMA IN HUNTSVILLE
E2: Biweekly Labor Report
C3: 2026-09
C6: Name: | E6: ='2026-08'!E6:H6 -> 0 | I6: A#: | J6: ='2026-08'!J6:L6 -> 0 | M6: Position #: | O6: ='2026-08'!O6:P6 -> 0 | Q6: Title: | R6: ='2026-08'!R6:T6 -> 0
C8: Department: | E8: ='2026-08'!E8:H8 -> Earth System Science Center | I8: Pay Period: | K8: ='2026-08'!K8:L8+14 -> 46113 | M8: to | N8: ='2026-08'!N8:O8+14 -> 46126 | Q8: FTE: | R8: ='2026-08'!R8 -> 1
C10: Home Labor: | E10: ='2026-08'!E10:H10 -> 740001 | I10: Check Date: | L10: =N8+10 -> 46136
C14: 6 digit Org/Index | D14: Account Code | E14: % Distribution | G14: COMMENTS
C15: =IF('2026-08'!C15=0,"",'2026-08'!C15) | D15: =IF('2026-08'!D15=0,"",'2026-08'!D15) | E15: =IF('2026-08'!E15=0,"",'2026-08'!E15)
C16: =IF('2026-08'!C16=0,"",'2026-08'!C16) | D16: =IF('2026-08'!D16=0,"",'2026-08'!D16) | E16: =IF('2026-08'!E16=0,"",'2026-08'!E16)
C17: =IF('2026-08'!C17=0,"",'2026-08'!C17) | D17: =IF('2026-08'!D17=0,"",'2026-08'!D17) | E17: =IF('2026-08'!E17=0,"",'2026-08'!E17)
C18: =IF('2026-08'!C18=0,"",'2026-08'!C18) | D18: =IF('2026-08'!D18=0,"",'2026-08'!D18) | E18: =IF('2026-08'!E18=0,"",'2026-08'!E18)
C19: =IF('2026-08'!C19=0,"",'2026-08'!C19) | D19: =IF('2026-08'!D19=0,"",'2026-08'!D19) | E19: =IF('2026-08'!E19=0,"",'2026-08'!E19)
C20: =IF('2026-08'!C20=0,"",'2026-08'!C20) | D20: =IF('2026-08'!D20=0,"",'2026-08'!D20) | E20: =IF('2026-08'!E20=0,"",'2026-08'!E20)
C21: =IF('2026-08'!C21=0,"",'2026-08'!C21) | D21: =IF('2026-08'!D21=0,"",'2026-08'!D21) | E21: =IF('2026-08'!E21=0,"",'2026-08'!E21)
C22: =IF('2026-08'!C22=0,"",'2026-08'!C22) | D22: =IF('2026-08'!D22=0,"",'2026-08'!D22) | E22: =IF('2026-08'!E22=0,"",'2026-08'!E22)
C23: =IF('2026-08'!C23=0,"",'2026-08'!C23) | D23: =IF('2026-08'!D23=0,"",'2026-08'!D23) | E23: =IF('2026-08'!E23=0,"",'2026-08'!E23)
C24: =IF('2026-08'!C24=0,"",'2026-08'!C24) | D24: =IF('2026-08'!D24=0,"",'2026-08'!D24) | E24: =IF('2026-08'!E24=0,"",'2026-08'!E24)
C25: =IF('2026-08'!C25=0,"",'2026-08'!C25) | D25: =IF('2026-08'!D25=0,"",'2026-08'!D25) | E25: =IF('2026-08'!E25=0,"",'2026-08'!E25)
C26: =IF('2026-08'!C26=0,"",'2026-08'!C26) | D26: =IF('2026-08'!D26=0,"",'2026-08'!D26) | E26: =IF('2026-08'!E26=0,"",'2026-08'!E26)
C27: Total Labor | E27: =SUM(E15:E26) -> 0 | G27: =IF(E27=100%,"","ERROR: TOTAL LABOR MUST BE 100%!!!") -> ERROR: TOTAL LABOR MUST BE 100%!!!
C28: I certify that the distribution of labor above represents the actual work performed during this reporting period.
C30: Employee Signature | Q30: Date
C32: Supervisor Signature | Q32: Date
C34: Budget Unit Head Signature | Q34: Date

Sheet 2026-10
C1: Payroll ID | E1: UNIVERSITY OF ALABAMA IN HUNTSVILLE
E2: Biweekly Labor Report
C3: 2026-10
C6: Name: | E6: ='2026-09'!E6:H6 -> 0 | I6: A#: | J6: ='2026-09'!J6:L6 -> 0 | M6: Position #: | O6: ='2026-09'!O6:P6 -> 0 | Q6: Title: | R6: ='2026-09'!R6:T6 -> 0
C8: Department: | E8: ='2026-09'!E8:H8 -> Earth System Science Center | I8: Pay Period: | K8: ='2026-09'!K8:L8+14 -> 46127 | M8: to | N8: ='2026-09'!N8:O8+14 -> 46140 | Q8: FTE: | R8: ='2026-09'!R8 -> 1
C10: Home Labor: | E10: ='2026-09'!E10:H10 -> 740001 | I10: Check Date: | L10: =N8+10 -> 46150
C14: 6 digit Org/Index | D14: Account Code | E14: % Distribution | G14: COMMENTS
C15: =IF('2026-09'!C15=0,"",'2026-09'!C15) | D15: =IF('2026-09'!D15=0,"",'2026-09'!D15) | E15: =IF('2026-09'!E15=0,"",'2026-09'!E15)
C16: =IF('2026-09'!C16=0,"",'2026-09'!C16) | D16: =IF('2026-09'!D16=0,"",'2026-09'!D16) | E16: =IF('2026-09'!E16=0,"",'2026-09'!E16)
C17: =IF('2026-09'!C17=0,"",'2026-09'!C17) | D17: =IF('2026-09'!D17=0,"",'2026-09'!D17) | E17: =IF('2026-09'!E17=0,"",'2026-09'!E17)
C18: =IF('2026-09'!C18=0,"",'2026-09'!C18) | D18: =IF('2026-09'!D18=0,"",'2026-09'!D18) | E18: =IF('2026-09'!E18=0,"",'2026-09'!E18)
C19: =IF('2026-09'!C19=0,"",'2026-09'!C19) | D19: =IF('2026-09'!D19=0,"",'2026-09'!D19) | E19: =IF('2026-09'!E19=0,"",'2026-09'!E19)
C20: =IF('2026-09'!C20=0,"",'2026-09'!C20) | D20: =IF('2026-09'!D20=0,"",'2026-09'!D20) | E20: =IF('2026-09'!E20=0,"",'2026-09'!E20)
C21: =IF('2026-09'!C21=0,"",'2026-09'!C21) | D21: =IF('2026-09'!D21=0,"",'2026-09'!D21) | E21: =IF('2026-09'!E21=0,"",'2026-09'!E21)
C22: =IF('2026-09'!C22=0,"",'2026-09'!C22) | D22: =IF('2026-09'!D22=0,"",'2026-09'!D22) | E22: =IF('2026-09'!E22=0,"",'2026-09'!E22)
C23: =IF('2026-09'!C23=0,"",'2026-09'!C23) | D23: =IF('2026-09'!D23=0,"",'2026-09'!D23) | E23: =IF('2026-09'!E23=0,"",'2026-09'!E23)
C24: =IF('2026-09'!C24=0,"",'2026-09'!C24) | D24: =IF('2026-09'!D24=0,"",'2026-09'!D24) | E24: =IF('2026-09'!E24=0,"",'2026-09'!E24)
C25: =IF('2026-09'!C25=0,"",'2026-09'!C25) | D25: =IF('2026-09'!D25=0,"",'2026-09'!D25) | E25: =IF('2026-09'!E25=0,"",'2026-09'!E25)
C26: =IF('2026-09'!C26=0,"",'2026-09'!C26) | D26: =IF('2026-09'!D26=0,"",'2026-09'!D26) | E26: =IF('2026-09'!E26=0,"",'2026-09'!E26)
C27: Total Labor | E27: =SUM(E15:E26) -> 0 | G27: =IF(E27=100%,"","ERROR: TOTAL LABOR MUST BE 100%!!!") -> ERROR: TOTAL LABOR MUST BE 100%!!!
C28: I certify that the distribution of labor above represents the actual work performed during this reporting period.
C30: Employee Signature | Q30: Date
C32: Supervisor Signature | Q32: Date
C34: Budget Unit Head Signature | Q34: Date

Sheet 2026-11
C1: Payroll ID | E1: UNIVERSITY OF ALABAMA IN HUNTSVILLE
E2: Biweekly Labor Report
C3: 2026-11
C6: Name: | E6: ='2026-10'!E6:H6 -> 0 | I6: A#: | J6: ='2026-10'!J6:L6 -> 0 | M6: Position #: | O6: ='2026-10'!O6:P6 -> 0 | Q6: Title: | R6: ='2026-10'!R6:T6 -> 0
C8: Department: | E8: ='2026-10'!E8:H8 -> Earth System Science Center | I8: Pay Period: | K8: ='2026-10'!K8:L8+14 -> 46141 | M8: to | N8: ='2026-10'!N8:O8+14 -> 46154 | Q8: FTE: | R8: ='2026-10'!R8 -> 1
C10: Home Labor: | E10: ='2026-10'!E10:H10 -> 740001 | I10: Check Date: | L10: =N8+10 -> 46164
C14: 6 digit Org/Index | D14: Account Code | E14: % Distribution | G14: COMMENTS
C15: =IF('2026-10'!C15=0,"",'2026-10'!C15) | D15: =IF('2026-10'!D15=0,"",'2026-10'!D15) | E15: =IF('2026-10'!E15=0,"",'2026-10'!E15)
C16: =IF('2026-10'!C16=0,"",'2026-10'!C16) | D16: =IF('2026-10'!D16=0,"",'2026-10'!D16) | E16: =IF('2026-10'!E16=0,"",'2026-10'!E16)
C17: =IF('2026-10'!C17=0,"",'2026-10'!C17) | D17: =IF('2026-10'!D17=0,"",'2026-10'!D17) | E17: =IF('2026-10'!E17=0,"",'2026-10'!E17)
C18: =IF('2026-10'!C18=0,"",'2026-10'!C18) | D18: =IF('2026-10'!D18=0,"",'2026-10'!D18) | E18: =IF('2026-10'!E18=0,"",'2026-10'!E18)
C19: =IF('2026-10'!C19=0,"",'2026-10'!C19) | D19: =IF('2026-10'!D19=0,"",'2026-10'!D19) | E19: =IF('2026-10'!E19=0,"",'2026-10'!E19)
C20: =IF('2026-10'!C20=0,"",'2026-10'!C20) | D20: =IF('2026-10'!D20=0,"",'2026-10'!D20) | E20: =IF('2026-10'!E20=0,"",'2026-10'!E20)
C21: =IF('2026-10'!C21=0,"",'2026-10'!C21) | D21: =IF('2026-10'!D21=0,"",'2026-10'!D21) | E21: =IF('2026-10'!E21=0,"",'2026-10'!E21)
C22: =IF('2026-10'!C22=0,"",'2026-10'!C22) | D22: =IF('2026-10'!D22=0,"",'2026-10'!D22) | E22: =IF('2026-10'!E22=0,"",'2026-10'!E22)
C23: =IF('2026-10'!C23=0,"",'2026-10'!C23) | D23: =IF('2026-10'!D23=0,"",'2026-10'!D23) | E23: =IF('2026-10'!E23=0,"",'2026-10'!E23)
C24: =IF('2026-10'!C24=0,"",'2026-10'!C24) | D24: =IF('2026-10'!D24=0,"",'2026-10'!D24) | E24: =IF('2026-10'!E24=0,"",'2026-10'!E24)
C25: =IF('2026-10'!C25=0,"",'2026-10'!C25) | D25: =IF('2026-10'!D25=0,"",'2026-10'!D25) | E25: =IF('2026-10'!E25=0,"",'2026-10'!E25)
C26: =IF('2026-10'!C26=0,"",'2026-10'!C26) | D26: =IF('2026-10'!D26=0,"",'2026-10'!D26) | E26: =IF('2026-10'!E26=0,"",'2026-10'!E26)
C27: Total Labor | E27: =SUM(E15:E26) -> 0 | G27: =IF(E27=100%,"","ERROR: TOTAL LABOR MUST BE 100%!!!") -> ERROR: TOTAL LABOR MUST BE 100%!!!
C28: I certify that the distribution of labor above represents the actual work performed during this reporting period.
C30: Employee Signature | Q30: Date
C32: Supervisor Signature | Q32: Date
C34: Budget Unit Head Signature | Q34: Date

Sheet 2026-12
C1: Payroll ID | E1: UNIVERSITY OF ALABAMA IN HUNTSVILLE
E2: Biweekly Labor Report
C3: 2026-12
C6: Name: | E6: ='2026-11'!E6:H6 -> 0 | I6: A#: | J6: ='2026-11'!J6:L6 -> 0 | M6: Position #: | O6: ='2026-11'!O6:P6 -> 0 | Q6: Title: | R6: ='2026-11'!R6:T6 -> 0
C8: Department: | E8: ='2026-11'!E8:H8 -> Earth System Science Center | I8: Pay Period: | K8: ='2026-11'!K8:L8+14 -> 46155 | M8: to | N8: ='2026-11'!N8:O8+14 -> 46168 | Q8: FTE: | R8: ='2026-11'!R8 -> 1
C10: Home Labor: | E10: ='2026-11'!E10:H10 -> 740001 | I10: Check Date: | L10: =N8+10 -> 46178
C14: 6 digit Org/Index | D14: Account Code | E14: % Distribution | G14: COMMENTS
C15: =IF('2026-11'!C15=0,"",'2026-11'!C15) | D15: =IF('2026-11'!D15=0,"",'2026-11'!D15) | E15: =IF('2026-11'!E15=0,"",'2026-11'!E15)
C16: =IF('2026-11'!C16=0,"",'2026-11'!C16) | D16: =IF('2026-11'!D16=0,"",'2026-11'!D16) | E16: =IF('2026-11'!E16=0,"",'2026-11'!E16)
C17: =IF('2026-11'!C17=0,"",'2026-11'!C17) | D17: =IF('2026-11'!D17=0,"",'2026-11'!D17) | E17: =IF('2026-11'!E17=0,"",'2026-11'!E17)
C18: =IF('2026-11'!C18=0,"",'2026-11'!C18) | D18: =IF('2026-11'!D18=0,"",'2026-11'!D18) | E18: =IF('2026-11'!E18=0,"",'2026-11'!E18)
C19: =IF('2026-11'!C19=0,"",'2026-11'!C19) | D19: =IF('2026-11'!D19=0,"",'2026-11'!D19) | E19: =IF('2026-11'!E19=0,"",'2026-11'!E19)
C20: =IF('2026-11'!C20=0,"",'2026-11'!C20) | D20: =IF('2026-11'!D20=0,"",'2026-11'!D20) | E20: =IF('2026-11'!E20=0,"",'2026-11'!E20)
C21: =IF('2026-11'!C21=0,"",'2026-11'!C21) | D21: =IF('2026-11'!D21=0,"",'2026-11'!D21) | E21: =IF('2026-11'!E21=0,"",'2026-11'!E21)
C22: =IF('2026-11'!C22=0,"",'2026-11'!C22) | D22: =IF('2026-11'!D22=0,"",'2026-11'!D22) | E22: =IF('2026-11'!E22=0,"",'2026-11'!E22)
C23: =IF('2026-11'!C23=0,"",'2026-11'!C23) | D23: =IF('2026-11'!D23=0,"",'2026-11'!D23) | E23: =IF('2026-11'!E23=0,"",'2026-11'!E23)
C24: =IF('2026-11'!C24=0,"",'2026-11'!C24) | D24: =IF('2026-11'!D24=0,"",'2026-11'!D24) | E24: =IF('2026-11'!E24=0,"",'2026-11'!E24)
C25: =IF('2026-11'!C25=0,"",'2026-11'!C25) | D25: =IF('2026-11'!D25=0,"",'2026-11'!D25) | E25: =IF('2026-11'!E25=0,"",'2026-11'!E25)
C26: =IF('2026-11'!C26=0,"",'2026-11'!C26) | D26: =IF('2026-11'!D26=0,"",'2026-11'!D26) | E26: =IF('2026-11'!E26=0,"",'2026-11'!E26)
C27: Total Labor | E27: =SUM(E15:E26) -> 0 | G27: =IF(E27=100%,"","ERROR: TOTAL LABOR MUST BE 100%!!!") -> ERROR: TOTAL LABOR MUST BE 100%!!!
C28: I certify that the distribution of labor above represents the actual work performed during this reporting period.
C30: Employee Signature | Q30: Date
C32: Supervisor Signature | Q32: Date
C34: Budget Unit Head Signature | Q34: Date

Sheet 2026-13
C1: Payroll ID | E1: UNIVERSITY OF ALABAMA IN HUNTSVILLE
E2: Biweekly Labor Report
C3: 2026-13
C6: Name: | E6: ='2026-12'!E6:H6 -> 0 | I6: A#: | J6: ='2026-12'!J6:L6 -> 0 | M6: Position #: | O6: ='2026-12'!O6:P6 -> 0 | Q6: Title: | R6: ='2026-12'!R6:T6 -> 0
C8: Department: | E8: ='2026-12'!E8:H8 -> Earth System Science Center | I8: Pay Period: | K8: ='2026-12'!K8:L8+14 -> 46169 | M8: to | N8: ='2026-12'!N8:O8+14 -> 46182 | Q8: FTE: | R8: ='2026-12'!R8 -> 1
C10: Home Labor: | E10: ='2026-12'!E10:H10 -> 740001 | I10: Check Date: | L10: =N8+10 -> 46192
C14: 6 digit Org/Index | D14: Account Code | E14: % Distribution | G14: COMMENTS
C15: =IF('2026-12'!C15=0,"",'2026-12'!C15) | D15: =IF('2026-12'!D15=0,"",'2026-12'!D15) | E15: =IF('2026-12'!E15=0,"",'2026-12'!E15)
C16: =IF('2026-12'!C16=0,"",'2026-12'!C16) | D16: =IF('2026-12'!D16=0,"",'2026-12'!D16) | E16: =IF('2026-12'!E16=0,"",'2026-12'!E16)
C17: =IF('2026-12'!C17=0,"",'2026-12'!C17) | D17: =IF('2026-12'!D17=0,"",'2026-12'!D17) | E17: =IF('2026-12'!E17=0,"",'2026-12'!E17)
C18: =IF('2026-12'!C18=0,"",'2026-12'!C18) | D18: =IF('2026-12'!D18=0,"",'2026-12'!D18) | E18: =IF('2026-12'!E18=0,"",'2026-12'!E18)
C19: =IF('2026-12'!C19=0,"",'2026-12'!C19) | D19: =IF('2026-12'!D19=0,"",'2026-12'!D19) | E19: =IF('2026-12'!E19=0,"",'2026-12'!E19)
C20: =IF('2026-12'!C20=0,"",'2026-12'!C20) | D20: =IF('2026-12'!D20=0,"",'2026-12'!D20) | E20: =IF('2026-12'!E20=0,"",'2026-12'!E20)
C21: =IF('2026-12'!C21=0,"",'2026-12'!C21) | D21: =IF('2026-12'!D21=0,"",'2026-12'!D21) | E21: =IF('2026-12'!E21=0,"",'2026-12'!E21)
C22: =IF('2026-12'!C22=0,"",'2026-12'!C22) | D22: =IF('2026-12'!D22=0,"",'2026-12'!D22) | E22: =IF('2026-12'!E22=0,"",'2026-12'!E22)
C23: =IF('2026-12'!C23=0,"",'2026-12'!C23) | D23: =IF('2026-12'!D23=0,"",'2026-12'!D23) | E23: =IF('2026-12'!E23=0,"",'2026-12'!E23)
C24: =IF('2026-12'!C24=0,"",'2026-12'!C24) | D24: =IF('2026-12'!D24=0,"",'2026-12'!D24) | E24: =IF('2026-12'!E24=0,"",'2026-12'!E24)
C25: =IF('2026-12'!C25=0,"",'2026-12'!C25) | D25: =IF('2026-12'!D25=0,"",'2026-12'!D25) | E25: =IF('2026-12'!E25=0,"",'2026-12'!E25)
C26: =IF('2026-12'!C26=0,"",'2026-12'!C26) | D26: =IF('2026-12'!D26=0,"",'2026-12'!D26) | E26: =IF('2026-12'!E26=0,"",'2026-12'!E26)
C27: Total Labor | E27: =SUM(E15:E26) -> 0 | G27: =IF(E27=100%,"","ERROR: TOTAL LABOR MUST BE 100%!!!") -> ERROR: TOTAL LABOR MUST BE 100%!!!
C28: I certify that the distribution of labor above represents the actual work performed during this reporting period.
C30: Employee Signature | Q30: Date
C32: Supervisor Signature | Q32: Date
C34: Budget Unit Head Signature | Q34: Date

Sheet 2026-14
C1: Payroll ID | E1: UNIVERSITY OF ALABAMA IN HUNTSVILLE
E2: Biweekly Labor Report
C3: 2026-14
C6: Name: | E6: ='2026-13'!E6:H6 -> 0 | I6: A#: | J6: ='2026-13'!J6:L6 -> 0 | M6: Position #: | O6: ='2026-13'!O6:P6 -> 0 | Q6: Title: | R6: ='2026-13'!R6:T6 -> 0
C8: Department: | E8: ='2026-13'!E8:H8 -> Earth System Science Center | I8: Pay Period: | K8: ='2026-13'!K8:L8+14 -> 46183 | M8: to | N8: ='2026-13'!N8:O8+14 -> 46196 | Q8: FTE: | R8: ='2026-13'!R8 -> 1
C10: Home Labor: | E10: ='2026-13'!E10:H10 -> 740001 | I10: Check Date: | L10: =N8+10 -> 46206
C14: 6 digit Org/Index | D14: Account Code | E14: % Distribution | G14: COMMENTS
C15: =IF('2026-13'!C15=0,"",'2026-13'!C15) | D15: =IF('2026-13'!D15=0,"",'2026-13'!D15) | E15: =IF('2026-13'!E15=0,"",'2026-13'!E15)
C16: =IF('2026-13'!C16=0,"",'2026-13'!C16) | D16: =IF('2026-13'!D16=0,"",'2026-13'!D16) | E16: =IF('2026-13'!E16=0,"",'2026-13'!E16)
C17: =IF('2026-13'!C17=0,"",'2026-13'!C17) | D17: =IF('2026-13'!D17=0,"",'2026-13'!D17) | E17: =IF('2026-13'!E17=0,"",'2026-13'!E17)
C18: =IF('2026-13'!C18=0,"",'2026-13'!C18) | D18: =IF('2026-13'!D18=0,"",'2026-13'!D18) | E18: =IF('2026-13'!E18=0,"",'2026-13'!E18)
C19: =IF('2026-13'!C19=0,"",'2026-13'!C19) | D19: =IF('2026-13'!D19=0,"",'2026-13'!D19) | E19: =IF('2026-13'!E19=0,"",'2026-13'!E19)
C20: =IF('2026-13'!C20=0,"",'2026-13'!C20) | D20: =IF('2026-13'!D20=0,"",'2026-13'!D20) | E20: =IF('2026-13'!E20=0,"",'2026-13'!E20)
C21: =IF('2026-13'!C21=0,"",'2026-13'!C21) | D21: =IF('2026-13'!D21=0,"",'2026-13'!D21) | E21: =IF('2026-13'!E21=0,"",'2026-13'!E21)
C22: =IF('2026-13'!C22=0,"",'2026-13'!C22) | D22: =IF('2026-13'!D22=0,"",'2026-13'!D22) | E22: =IF('2026-13'!E22=0,"",'2026-13'!E22)
C23: =IF('2026-13'!C23=0,"",'2026-13'!C23) | D23: =IF('2026-13'!D23=0,"",'2026-13'!D23) | E23: =IF('2026-13'!E23=0,"",'2026-13'!E23)
C24: =IF('2026-13'!C24=0,"",'2026-13'!C24) | D24: =IF('2026-13'!D24=0,"",'2026-13'!D24) | E24: =IF('2026-13'!E24=0,"",'2026-13'!E24)
C25: =IF('2026-13'!C25=0,"",'2026-13'!C25) | D25: =IF('2026-13'!D25=0,"",'2026-13'!D25) | E25: =IF('2026-13'!E25=0,"",'2026-13'!E25)
C26: =IF('2026-13'!C26=0,"",'2026-13'!C26) | D26: =IF('2026-13'!D26=0,"",'2026-13'!D26) | E26: =IF('2026-13'!E26=0,"",'2026-13'!E26)
C27: Total Labor | E27: =SUM(E15:E26) -> 0 | G27: =IF(E27=100%,"","ERROR: TOTAL LABOR MUST BE 100%!!!") -> ERROR: TOTAL LABOR MUST BE 100%!!!
C28: I certify that the distribution of labor above represents the actual work performed during this reporting period.
C30: Employee Signature | Q30: Date
C32: Supervisor Signature | Q32: Date
C34: Budget Unit Head Signature | Q34: Date

Sheet 2026-15
C1: Payroll ID | E1: UNIVERSITY OF ALABAMA IN HUNTSVILLE
E2: Biweekly Labor Report
C3: 2026-15
C6: Name: | E6: ='2026-14'!E6:H6 -> 0 | I6: A#: | J6: ='2026-14'!J6:L6 -> 0 | M6: Position #: | O6: ='2026-14'!O6:P6 -> 0 | Q6: Title: | R6: ='2026-14'!R6:T6 -> 0
C8: Department: | E8: ='2026-14'!E8:H8 -> Earth System Science Center | I8: Pay Period: | K8: ='2026-14'!K8:L8+14 -> 46197 | M8: to | N8: ='2026-14'!N8:O8+14 -> 46210 | Q8: FTE: | R8: ='2026-14'!R8 -> 1
C10: Home Labor: | E10: ='2026-14'!E10:H10 -> 740001 | I10: Check Date: | L10: =N8+10 -> 46220
C14: 6 digit Org/Index | D14: Account Code | E14: % Distribution | G14: COMMENTS
C15: =IF('2026-14'!C15=0,"",'2026-14'!C15) | D15: =IF('2026-14'!D15=0,"",'2026-14'!D15) | E15: =IF('2026-14'!E15=0,"",'2026-14'!E15)
C16: =IF('2026-14'!C16=0,"",'2026-14'!C16) | D16: =IF('2026-14'!D16=0,"",'2026-14'!D16) | E16: =IF('2026-14'!E16=0,"",'2026-14'!E16)
C17: =IF('2026-14'!C17=0,"",'2026-14'!C17) | D17: =IF('2026-14'!D17=0,"",'2026-14'!D17) | E17: =IF('2026-14'!E17=0,"",'2026-14'!E17)
C18: =IF('2026-14'!C18=0,"",'2026-14'!C18) | D18: =IF('2026-14'!D18=0,"",'2026-14'!D18) | E18: =IF('2026-14'!E18=0,"",'2026-14'!E18)
C19: =IF('2026-14'!C19=0,"",'2026-14'!C19) | D19: =IF('2026-14'!D19=0,"",'2026-14'!D19) | E19: =IF('2026-14'!E19=0,"",'2026-14'!E19)
C20: =IF('2026-14'!C20=0,"",'2026-14'!C20) | D20: =IF('2026-14'!D20=0,"",'2026-14'!D20) | E20: =IF('2026-14'!E20=0,"",'2026-14'!E20)
C21: =IF('2026-14'!C21=0,"",'2026-14'!C21) | D21: =IF('2026-14'!D21=0,"",'2026-14'!D21) | E21: =IF('2026-14'!E21=0,"",'2026-14'!E21)
C22: =IF('2026-14'!C22=0,"",'2026-14'!C22) | D22: =IF('2026-14'!D22=0,"",'2026-14'!D22) | E22: =IF('2026-14'!E22=0,"",'2026-14'!E22)
C23: =IF('2026-14'!C23=0,"",'2026-14'!C23) | D23: =IF('2026-14'!D23=0,"",'2026-14'!D23) | E23: =IF('2026-14'!E23=0,"",'2026-14'!E23)
C24: =IF('2026-14'!C24=0,"",'2026-14'!C24) | D24: =IF('2026-14'!D24=0,"",'2026-14'!D24) | E24: =IF('2026-14'!E24=0,"",'2026-14'!E24)
C25: =IF('2026-14'!C25=0,"",'2026-14'!C25) | D25: =IF('2026-14'!D25=0,"",'2026-14'!D25) | E25: =IF('2026-14'!E25=0,"",'2026-14'!E25)
C26: =IF('2026-14'!C26=0,"",'2026-14'!C26) | D26: =IF('2026-14'!D26=0,"",'2026-14'!D26) | E26: =IF('2026-14'!E26=0,"",'2026-14'!E26)
C27: Total Labor | E27: =SUM(E15:E26) -> 0 | G27: =IF(E27=100%,"","ERROR: TOTAL LABOR MUST BE 100%!!!") -> ERROR: TOTAL LABOR MUST BE 100%!!!
C28: I certify that the distribution of labor above represents the actual work performed during this reporting period.
C30: Employee Signature | Q30: Date
C32: Supervisor Signature | Q32: Date
C34: Budget Unit Head Signature | Q34: Date

Sheet 2026-16
C1: Payroll ID | E1: UNIVERSITY OF ALABAMA IN HUNTSVILLE
E2: Biweekly Labor Report
C3: 2026-16
C6: Name: | E6: ='2026-15'!E6:H6 -> 0 | I6: A#: | J6: ='2026-15'!J6:L6 -> 0 | M6: Position #: | O6: ='2026-15'!O6:P6 -> 0 | Q6: Title: | R6: ='2026-15'!R6:T6 -> 0
C8: Department: | E8: ='2026-15'!E8:H8 -> Earth System Science Center | I8: Pay Period: | K8: ='2026-15'!K8:L8+14 -> 46211 | M8: to | N8: ='2026-15'!N8:O8+14 -> 46224 | Q8: FTE: | R8: ='2026-15'!R8 -> 1
C10: Home Labor: | E10: ='2026-15'!E10:H10 -> 740001 | I10: Check Date: | L10: =N8+10 -> 46234
C14: 6 digit Org/Index | D14: Account Code | E14: % Distribution | G14: COMMENTS
C15: =IF('2026-15'!C15=0,"",'2026-15'!C15) | D15: =IF('2026-15'!D15=0,"",'2026-15'!D15) | E15: =IF('2026-15'!E15=0,"",'2026-15'!E15)
C16: =IF('2026-15'!C16=0,"",'2026-15'!C16) | D16: =IF('2026-15'!D16=0,"",'2026-15'!D16) | E16: =IF('2026-15'!E16=0,"",'2026-15'!E16)
C17: =IF('2026-15'!C17=0,"",'2026-15'!C17) | D17: =IF('2026-15'!D17=0,"",'2026-15'!D17) | E17: =IF('2026-15'!E17=0,"",'2026-15'!E17)
C18: =IF('2026-15'!C18=0,"",'2026-15'!C18) | D18: =IF('2026-15'!D18=0,"",'2026-15'!D18) | E18: =IF('2026-15'!E18=0,"",'2026-15'!E18)
C19: =IF('2026-15'!C19=0,"",'2026-15'!C19) | D19: =IF('2026-15'!D19=0,"",'2026-15'!D19) | E19: =IF('2026-15'!E19=0,"",'2026-15'!E19)
C20: =IF('2026-15'!C20=0,"",'2026-15'!C20) | D20: =IF('2026-15'!D20=0,"",'2026-15'!D20) | E20: =IF('2026-15'!E20=0,"",'2026-15'!E20)
C21: =IF('2026-15'!C21=0,"",'2026-15'!C21) | D21: =IF('2026-15'!D21=0,"",'2026-15'!D21) | E21: =IF('2026-15'!E21=0,"",'2026-15'!E21)
C22: =IF('2026-15'!C22=0,"",'2026-15'!C22) | D22: =IF('2026-15'!D22=0,"",'2026-15'!D22) | E22: =IF('2026-15'!E22=0,"",'2026-15'!E22)
C23: =IF('2026-15'!C23=0,"",'2026-15'!C23) | D23: =IF('2026-15'!D23=0,"",'2026-15'!D23) | E23: =IF('2026-15'!E23=0,"",'2026-15'!E23)
C24: =IF('2026-15'!C24=0,"",'2026-15'!C24) | D24: =IF('2026-15'!D24=0,"",'2026-15'!D24) | E24: =IF('2026-15'!E24=0,"",'2026-15'!E24)
C25: =IF('2026-15'!C25=0,"",'2026-15'!C25) | D25: =IF('2026-15'!D25=0,"",'2026-15'!D25) | E25: =IF('2026-15'!E25=0,"",'2026-15'!E25)
C26: =IF('2026-15'!C26=0,"",'2026-15'!C26) | D26: =IF('2026-15'!D26=0,"",'2026-15'!D26) | E26: =IF('2026-15'!E26=0,"",'2026-15'!E26)
C27: Total Labor | E27: =SUM(E15:E26) -> 0 | G27: =IF(E27=100%,"","ERROR: TOTAL LABOR MUST BE 100%!!!") -> ERROR: TOTAL LABOR MUST BE 100%!!!
C28: I certify that the distribution of labor above represents the actual work performed during this reporting period.
C30: Employee Signature | Q30: Date
C32: Supervisor Signature | Q32: Date
C34: Budget Unit Head Signature | Q34: Date

Sheet 2026-17
C1: Payroll ID | E1: UNIVERSITY OF ALABAMA IN HUNTSVILLE
E2: Biweekly Labor Report
C3: 2026-17
C6: Name: | E6: ='2026-16'!E6:H6 -> 0 | I6: A#: | J6: ='2026-16'!J6:L6 -> 0 | M6: Position #: | O6: ='2026-16'!O6:P6 -> 0 | Q6: Title: | R6: ='2026-16'!R6:T6 -> 0
C8: Department: | E8: ='2026-16'!E8:H8 -> Earth System Science Center | I8: Pay Period: | K8: ='2026-16'!K8:L8+14 -> 46225 | M8: to | N8: ='2026-16'!N8:O8+14 -> 46238 | Q8: FTE: | R8: ='2026-16'!R8 -> 1
C10: Home Labor: | E10: ='2026-16'!E10:H10 -> 740001 | I10: Check Date: | L10: =N8+10 -> 46248
C14: 6 digit Org/Index | D14: Account Code | E14: % Distribution | G14: COMMENTS
C15: =IF('2026-16'!C15=0,"",'2026-16'!C15) | D15: =IF('2026-16'!D15=0,"",'2026-16'!D15) | E15: =IF('2026-16'!E15=0,"",'2026-16'!E15)
C16: =IF('2026-16'!C16=0,"",'2026-16'!C16) | D16: =IF('2026-16'!D16=0,"",'2026-16'!D16) | E16: =IF('2026-16'!E16=0,"",'2026-16'!E16)
C17: =IF('2026-16'!C17=0,"",'2026-16'!C17) | D17: =IF('2026-16'!D17=0,"",'2026-16'!D17) | E17: =IF('2026-16'!E17=0,"",'2026-16'!E17)
C18: =IF('2026-16'!C18=0,"",'2026-16'!C18) | D18: =IF('2026-16'!D18=0,"",'2026-16'!D18) | E18: =IF('2026-16'!E18=0,"",'2026-16'!E18)
C19: =IF('2026-16'!C19=0,"",'2026-16'!C19) | D19: =IF('2026-16'!D19=0,"",'2026-16'!D19) | E19: =IF('2026-16'!E19=0,"",'2026-16'!E19)
C20: =IF('2026-16'!C20=0,"",'2026-16'!C20) | D20: =IF('2026-16'!D20=0,"",'2026-16'!D20) | E20: =IF('2026-16'!E20=0,"",'2026-16'!E20)
C21: =IF('2026-16'!C21=0,"",'2026-16'!C21) | D21: =IF('2026-16'!D21=0,"",'2026-16'!D21) | E21: =IF('2026-16'!E21=0,"",'2026-16'!E21)
C22: =IF('2026-16'!C22=0,"",'2026-16'!C22) | D22: =IF('2026-16'!D22=0,"",'2026-16'!D22) | E22: =IF('2026-16'!E22=0,"",'2026-16'!E22)
C23: =IF('2026-16'!C23=0,"",'2026-16'!C23) | D23: =IF('2026-16'!D23=0,"",'2026-16'!D23) | E23: =IF('2026-16'!E23=0,"",'2026-16'!E23)
C24: =IF('2026-16'!C24=0,"",'2026-16'!C24) | D24: =IF('2026-16'!D24=0,"",'2026-16'!D24) | E24: =IF('2026-16'!E24=0,"",'2026-16'!E24)
C25: =IF('2026-16'!C25=0,"",'2026-16'!C25) | D25: =IF('2026-16'!D25=0,"",'2026-16'!D25) | E25: =IF('2026-16'!E25=0,"",'2026-16'!E25)
C26: =IF('2026-16'!C26=0,"",'2026-16'!C26) | D26: =IF('2026-16'!D26=0,"",'2026-16'!D26) | E26: =IF('2026-16'!E26=0,"",'2026-16'!E26)
C27: Total Labor | E27: =SUM(E15:E26) -> 0 | G27: =IF(E27=100%,"","ERROR: TOTAL LABOR MUST BE 100%!!!") -> ERROR: TOTAL LABOR MUST BE 100%!!!
C28: I certify that the distribution of labor above represents the actual work performed during this reporting period.
C30: Employee Signature | Q30: Date
C32: Supervisor Signature | Q32: Date
C34: Budget Unit Head Signature | Q34: Date

Sheet 2026-18
C1: Payroll ID | E1: UNIVERSITY OF ALABAMA IN HUNTSVILLE
E2: Biweekly Labor Report
C3: 2026-18
C6: Name: | E6: ='2026-17'!E6:H6 -> 0 | I6: A#: | J6: ='2026-17'!J6:L6 -> 0 | M6: Position #: | O6: ='2026-17'!O6:P6 -> 0 | Q6: Title: | R6: ='2026-17'!R6:T6 -> 0
C8: Department: | E8: ='2026-17'!E8:H8 -> Earth System Science Center | I8: Pay Period: | K8: ='2026-17'!K8:L8+14 -> 46239 | M8: to | N8: ='2026-17'!N8:O8+14 -> 46252 | Q8: FTE: | R8: ='2026-17'!R8 -> 1
C10: Home Labor: | E10: ='2026-17'!E10:H10 -> 740001 | I10: Check Date: | L10: =N8+10 -> 46262
C14: 6 digit Org/Index | D14: Account Code | E14: % Distribution | G14: COMMENTS
C15: =IF('2026-17'!C15=0,"",'2026-17'!C15) | D15: =IF('2026-17'!D15=0,"",'2026-17'!D15) | E15: =IF('2026-17'!E15=0,"",'2026-17'!E15)
C16: =IF('2026-17'!C16=0,"",'2026-17'!C16) | D16: =IF('2026-17'!D16=0,"",'2026-17'!D16) | E16: =IF('2026-17'!E16=0,"",'2026-17'!E16)
C17: =IF('2026-17'!C17=0,"",'2026-17'!C17) | D17: =IF('2026-17'!D17=0,"",'2026-17'!D17) | E17: =IF('2026-17'!E17=0,"",'2026-17'!E17)
C18: =IF('2026-17'!C18=0,"",'2026-17'!C18) | D18: =IF('2026-17'!D18=0,"",'2026-17'!D18) | E18: =IF('2026-17'!E18=0,"",'2026-17'!E18)
C19: =IF('2026-17'!C19=0,"",'2026-17'!C19) | D19: =IF('2026-17'!D19=0,"",'2026-17'!D19) | E19: =IF('2026-17'!E19=0,"",'2026-17'!E19)
C20: =IF('2026-17'!C20=0,"",'2026-17'!C20) | D20: =IF('2026-17'!D20=0,"",'2026-17'!D20) | E20: =IF('2026-17'!E20=0,"",'2026-17'!E20)
C21: =IF('2026-17'!C21=0,"",'2026-17'!C21) | D21: =IF('2026-17'!D21=0,"",'2026-17'!D21) | E21: =IF('2026-17'!E21=0,"",'2026-17'!E21)
C22: =IF('2026-17'!C22=0,"",'2026-17'!C22) | D22: =IF('2026-17'!D22=0,"",'2026-17'!D22) | E22: =IF('2026-17'!E22=0,"",'2026-17'!E22)
C23: =IF('2026-17'!C23=0,"",'2026-17'!C23) | D23: =IF('2026-17'!D23=0,"",'2026-17'!D23) | E23: =IF('2026-17'!E23=0,"",'2026-17'!E23)
C24: =IF('2026-17'!C24=0,"",'2026-17'!C24) | D24: =IF('2026-17'!D24=0,"",'2026-17'!D24) | E24: =IF('2026-17'!E24=0,"",'2026-17'!E24)
C25: =IF('2026-17'!C25=0,"",'2026-17'!C25) | D25: =IF('2026-17'!D25=0,"",'2026-17'!D25) | E25: =IF('2026-17'!E25=0,"",'2026-17'!E25)
C26: =IF('2026-17'!C26=0,"",'2026-17'!C26) | D26: =IF('2026-17'!D26=0,"",'2026-17'!D26) | E26: =IF('2026-17'!E26=0,"",'2026-17'!E26)
C27: Total Labor | E27: =SUM(E15:E26) -> 0 | G27: =IF(E27=100%,"","ERROR: TOTAL LABOR MUST BE 100%!!!") -> ERROR: TOTAL LABOR MUST BE 100%!!!
C28: I certify that the distribution of labor above represents the actual work performed during this reporting period.
C30: Employee Signature | Q30: Date
C32: Supervisor Signature | Q32: Date
C34: Budget Unit Head Signature | Q34: Date

Sheet 2026-19
C1: Payroll ID | E1: UNIVERSITY OF ALABAMA IN HUNTSVILLE
E2: Biweekly Labor Report
C3: 2026-19
C6: Name: | E6: ='2026-18'!E6:H6 -> 0 | I6: A#: | J6: ='2026-18'!J6:L6 -> 0 | M6: Position #: | O6: ='2026-18'!O6:P6 -> 0 | Q6: Title: | R6: ='2026-18'!R6:T6 -> 0
C8: Department: | E8: ='2026-18'!E8:H8 -> Earth System Science Center | I8: Pay Period: | K8: ='2026-18'!K8:L8+14 -> 46253 | M8: to | N8: ='2026-18'!N8:O8+14 -> 46266 | Q8: FTE: | R8: ='2026-18'!R8 -> 1
C10: Home Labor: | E10: ='2026-18'!E10:H10 -> 740001 | I10: Check Date: | L10: =N8+10 -> 46276
C14: 6 digit Org/Index | D14: Account Code | E14: % Distribution | G14: COMMENTS
C15: =IF('2026-18'!C15=0,"",'2026-18'!C15) | D15: =IF('2026-18'!D15=0,"",'2026-18'!D15) | E15: =IF('2026-18'!E15=0,"",'2026-18'!E15)
C16: =IF('2026-18'!C16=0,"",'2026-18'!C16) | D16: =IF('2026-18'!D16=0,"",'2026-18'!D16) | E16: =IF('2026-18'!E16=0,"",'2026-18'!E16)
C17: =IF('2026-18'!C17=0,"",'2026-18'!C17) | D17: =IF('2026-18'!D17=0,"",'2026-18'!D17) | E17: =IF('2026-18'!E17=0,"",'2026-18'!E17)
C18: =IF('2026-18'!C18=0,"",'2026-18'!C18) | D18: =IF('2026-18'!D18=0,"",'2026-18'!D18) | E18: =IF('2026-18'!E18=0,"",'2026-18'!E18)
C19: =IF('2026-18'!C19=0,"",'2026-18'!C19) | D19: =IF('2026-18'!D19=0,"",'2026-18'!D19) | E19: =IF('2026-18'!E19=0,"",'2026-18'!E19)
C20: =IF('2026-18'!C20=0,"",'2026-18'!C20) | D20: =IF('2026-18'!D20=0,"",'2026-18'!D20) | E20: =IF('2026-18'!E20=0,"",'2026-18'!E20)
C21: =IF('2026-18'!C21=0,"",'2026-18'!C21) | D21: =IF('2026-18'!D21=0,"",'2026-18'!D21) | E21: =IF('2026-18'!E21=0,"",'2026-18'!E21)
C22: =IF('2026-18'!C22=0,"",'2026-18'!C22) | D22: =IF('2026-18'!D22=0,"",'2026-18'!D22) | E22: =IF('2026-18'!E22=0,"",'2026-18'!E22)
C23: =IF('2026-18'!C23=0,"",'2026-18'!C23) | D23: =IF('2026-18'!D23=0,"",'2026-18'!D23) | E23: =IF('2026-18'!E23=0,"",'2026-18'!E23)
C24: =IF('2026-18'!C24=0,"",'2026-18'!C24) | D24: =IF('2026-18'!D24=0,"",'2026-18'!D24) | E24: =IF('2026-18'!E24=0,"",'2026-18'!E24)
C25: =IF('2026-18'!C25=0,"",'2026-18'!C25) | D25: =IF('2026-18'!D25=0,"",'2026-18'!D25) | E25: =IF('2026-18'!E25=0,"",'2026-18'!E25)
C26: =IF('2026-18'!C26=0,"",'2026-18'!C26) | D26: =IF('2026-18'!D26=0,"",'2026-18'!D26) | E26: =IF('2026-18'!E26=0,"",'2026-18'!E26)
C27: Total Labor | E27: =SUM(E15:E26) -> 0 | G27: =IF(E27=100%,"","ERROR: TOTAL LABOR MUST BE 100%!!!") -> ERROR: TOTAL LABOR MUST BE 100%!!!
C28: I certify that the distribution of labor above represents the actual work performed during this reporting period.
C30: Employee Signature | Q30: Date
C32: Supervisor Signature | Q32: Date
C34: Budget Unit Head Signature | Q34: Date

Sheet 2026-20
C1: Payroll ID | E1: UNIVERSITY OF ALABAMA IN HUNTSVILLE
E2: Biweekly Labor Report
C3: 2026-20
C6: Name: | E6: ='2026-19'!E6:H6 -> 0 | I6: A#: | J6: ='2026-19'!J6:L6 -> 0 | M6: Position #: | O6: ='2026-19'!O6:P6 -> 0 | Q6: Title: | R6: ='2026-19'!R6:T6 -> 0
C8: Department: | E8: ='2026-19'!E8:H8 -> Earth System Science Center | I8: Pay Period: | K8: ='2026-19'!K8:L8+14 -> 46267 | M8: to | N8: ='2026-19'!N8:O8+14 -> 46280 | Q8: FTE: | R8: ='2026-19'!R8 -> 1
C10: Home Labor: | E10: ='2026-19'!E10:H10 -> 740001 | I10: Check Date: | L10: =N8+10 -> 46290
C14: 6 digit Org/Index | D14: Account Code | E14: % Distribution | G14: COMMENTS
C15: =IF('2026-19'!C15=0,"",'2026-19'!C15) | D15: =IF('2026-19'!D15=0,"",'2026-19'!D15) | E15: =IF('2026-19'!E15=0,"",'2026-19'!E15)
C16: =IF('2026-19'!C16=0,"",'2026-19'!C16) | D16: =IF('2026-19'!D16=0,"",'2026-19'!D16) | E16: =IF('2026-19'!E16=0,"",'2026-19'!E16)
C17: =IF('2026-19'!C17=0,"",'2026-19'!C17) | D17: =IF('2026-19'!D17=0,"",'2026-19'!D17) | E17: =IF('2026-19'!E17=0,"",'2026-19'!E17)
C18: =IF('2026-19'!C18=0,"",'2026-19'!C18) | D18: =IF('2026-19'!D18=0,"",'2026-19'!D18) | E18: =IF('2026-19'!E18=0,"",'2026-19'!E18)
C19: =IF('2026-19'!C19=0,"",'2026-19'!C19) | D19: =IF('2026-19'!D19=0,"",'2026-19'!D19) | E19: =IF('2026-19'!E19=0,"",'2026-19'!E19)
C20: =IF('2026-19'!C20=0,"",'2026-19'!C20) | D20: =IF('2026-19'!D20=0,"",'2026-19'!D20) | E20: =IF('2026-19'!E20=0,"",'2026-19'!E20)
C21: =IF('2026-19'!C21=0,"",'2026-19'!C21) | D21: =IF('2026-19'!D21=0,"",'2026-19'!D21) | E21: =IF('2026-19'!E21=0,"",'2026-19'!E21)
C22: =IF('2026-19'!C22=0,"",'2026-19'!C22) | D22: =IF('2026-19'!D22=0,"",'2026-19'!D22) | E22: =IF('2026-19'!E22=0,"",'2026-19'!E22)
C23: =IF('2026-19'!C23=0,"",'2026-19'!C23) | D23: =IF('2026-19'!D23=0,"",'2026-19'!D23) | E23: =IF('2026-19'!E23=0,"",'2026-19'!E23)
C24: =IF('2026-19'!C24=0,"",'2026-19'!C24) | D24: =IF('2026-19'!D24=0,"",'2026-19'!D24) | E24: =IF('2026-19'!E24=0,"",'2026-19'!E24)
C25: =IF('2026-19'!C25=0,"",'2026-19'!C25) | D25: =IF('2026-19'!D25=0,"",'2026-19'!D25) | E25: =IF('2026-19'!E25=0,"",'2026-19'!E25)
C26: =IF('2026-19'!C26=0,"",'2026-19'!C26) | D26: =IF('2026-19'!D26=0,"",'2026-19'!D26) | E26: =IF('2026-19'!E26=0,"",'2026-19'!E26)
C27: Total Labor | E27: =SUM(E15:E26) -> 0 | G27: =IF(E27=100%,"","ERROR: TOTAL LABOR MUST BE 100%!!!") -> ERROR: TOTAL LABOR MUST BE 100%!!!
C28: I certify that the distribution of labor above represents the actual work performed during this reporting period.
C30: Employee Signature | Q30: Date
C32: Supervisor Signature | Q32: Date
C34: Budget Unit Head Signature | Q34: Date

Sheet 2026-21
C1: Payroll ID | E1: UNIVERSITY OF ALABAMA IN HUNTSVILLE
E2: Biweekly Labor Report
C3: 2026-21
C6: Name: | E6: ='2026-20'!E6:H6 -> 0 | I6: A#: | J6: ='2026-20'!J6:L6 -> 0 | M6: Position #: | O6: ='2026-20'!O6:P6 -> 0 | Q6: Title: | R6: ='2026-20'!R6:T6 -> 0
C8: Department: | E8: ='2026-20'!E8:H8 -> Earth System Science Center | I8: Pay Period: | K8: ='2026-20'!K8:L8+14 -> 46281 | M8: to | N8: ='2026-20'!N8:O8+14 -> 46294 | Q8: FTE: | R8: ='2026-20'!R8 -> 1
C10: Home Labor: | E10: ='2026-20'!E10:H10 -> 740001 | I10: Check Date: | L10: =N8+10 -> 46304
C14: 6 digit Org/Index | D14: Account Code | E14: % Distribution | G14: COMMENTS
C15: =IF('2026-20'!C15=0,"",'2026-20'!C15) | D15: =IF('2026-20'!D15=0,"",'2026-20'!D15) | E15: =IF('2026-20'!E15=0,"",'2026-20'!E15)
C16: =IF('2026-20'!C16=0,"",'2026-20'!C16) | D16: =IF('2026-20'!D16=0,"",'2026-20'!D16) | E16: =IF('2026-20'!E16=0,"",'2026-20'!E16)
C17: =IF('2026-20'!C17=0,"",'2026-20'!C17) | D17: =IF('2026-20'!D17=0,"",'2026-20'!D17) | E17: =IF('2026-20'!E17=0,"",'2026-20'!E17)
C18: =IF('2026-20'!C18=0,"",'2026-20'!C18) | D18: =IF('2026-20'!D18=0,"",'2026-20'!D18) | E18: =IF('2026-20'!E18=0,"",'2026-20'!E18)
C19: =IF('2026-20'!C19=0,"",'2026-20'!C19) | D19: =IF('2026-20'!D19=0,"",'2026-20'!D19) | E19: =IF('2026-20'!E19=0,"",'2026-20'!E19)
C20: =IF('2026-20'!C20=0,"",'2026-20'!C20) | D20: =IF('2026-20'!D20=0,"",'2026-20'!D20) | E20: =IF('2026-20'!E20=0,"",'2026-20'!E20)
C21: =IF('2026-20'!C21=0,"",'2026-20'!C21) | D21: =IF('2026-20'!D21=0,"",'2026-20'!D21) | E21: =IF('2026-20'!E21=0,"",'2026-20'!E21)
C22: =IF('2026-20'!C22=0,"",'2026-20'!C22) | D22: =IF('2026-20'!D22=0,"",'2026-20'!D22) | E22: =IF('2026-20'!E22=0,"",'2026-20'!E22)
C23: =IF('2026-20'!C23=0,"",'2026-20'!C23) | D23: =IF('2026-20'!D23=0,"",'2026-20'!D23) | E23: =IF('2026-20'!E23=0,"",'2026-20'!E23)
C24: =IF('2026-20'!C24=0,"",'2026-20'!C24) | D24: =IF('2026-20'!D24=0,"",'2026-20'!D24) | E24: =IF('2026-20'!E24=0,"",'2026-20'!E24)
C25: =IF('2026-20'!C25=0,"",'2026-20'!C25) | D25: =IF('2026-20'!D25=0,"",'2026-20'!D25) | E25: =IF('2026-20'!E25=0,"",'2026-20'!E25)
C26: =IF('2026-20'!C26=0,"",'2026-20'!C26) | D26: =IF('2026-20'!D26=0,"",'2026-20'!D26) | E26: =IF('2026-20'!E26=0,"",'2026-20'!E26)
C27: Total Labor | E27: =SUM(E15:E26) -> 0 | G27: =IF(E27=100%,"","ERROR: TOTAL LABOR MUST BE 100%!!!") -> ERROR: TOTAL LABOR MUST BE 100%!!!
C28: I certify that the distribution of labor above represents the actual work performed during this reporting period.
C30: Employee Signature | Q30: Date
C32: Supervisor Signature | Q32: Date
C34: Budget Unit Head Signature | Q34: Date

Sheet 2026-22
C1: Payroll ID | E1: UNIVERSITY OF ALABAMA IN HUNTSVILLE
E2: Biweekly Labor Report
C3: 2026-22
C6: Name: | E6: ='2026-21'!E6:H6 -> 0 | I6: A#: | J6: ='2026-21'!J6:L6 -> 0 | M6: Position #: | O6: ='2026-21'!O6:P6 -> 0 | Q6: Title: | R6: ='2026-21'!R6:T6 -> 0
C8: Department: | E8: ='2026-21'!E8:H8 -> Earth System Science Center | I8: Pay Period: | K8: ='2026-21'!K8:L8+14 -> 46295 | M8: to | N8: ='2026-21'!N8:O8+14 -> 46308 | Q8: FTE: | R8: ='2026-21'!R8 -> 1
C10: Home Labor: | E10: ='2026-21'!E10:H10 -> 740001 | I10: Check Date: | L10: =N8+10 -> 46318
C14: 6 digit Org/Index | D14: Account Code | E14: % Distribution | G14: COMMENTS
C15: =IF('2026-21'!C15=0,"",'2026-21'!C15) | D15: =IF('2026-21'!D15=0,"",'2026-21'!D15) | E15: =IF('2026-21'!E15=0,"",'2026-21'!E15)
C16: =IF('2026-21'!C16=0,"",'2026-21'!C16) | D16: =IF('2026-21'!D16=0,"",'2026-21'!D16) | E16: =IF('2026-21'!E16=0,"",'2026-21'!E16)
C17: =IF('2026-21'!C17=0,"",'2026-21'!C17) | D17: =IF('2026-21'!D17=0,"",'2026-21'!D17) | E17: =IF('2026-21'!E17=0,"",'2026-21'!E17)
C18: =IF('2026-21'!C18=0,"",'2026-21'!C18) | D18: =IF('2026-21'!D18=0,"",'2026-21'!D18) | E18: =IF('2026-21'!E18=0,"",'2026-21'!E18)
C19: =IF('2026-21'!C19=0,"",'2026-21'!C19) | D19: =IF('2026-21'!D19=0,"",'2026-21'!D19) | E19: =IF('2026-21'!E19=0,"",'2026-21'!E19)
C20: =IF('2026-21'!C20=0,"",'2026-21'!C20) | D20: =IF('2026-21'!D20=0,"",'2026-21'!D20) | E20: =IF('2026-21'!E20=0,"",'2026-21'!E20)
C21: =IF('2026-21'!C21=0,"",'2026-21'!C21) | D21: =IF('2026-21'!D21=0,"",'2026-21'!D21) | E21: =IF('2026-21'!E21=0,"",'2026-21'!E21)
C22: =IF('2026-21'!C22=0,"",'2026-21'!C22) | D22: =IF('2026-21'!D22=0,"",'2026-21'!D22) | E22: =IF('2026-21'!E22=0,"",'2026-21'!E22)
C23: =IF('2026-21'!C23=0,"",'2026-21'!C23) | D23: =IF('2026-21'!D23=0,"",'2026-21'!D23) | E23: =IF('2026-21'!E23=0,"",'2026-21'!E23)
C24: =IF('2026-21'!C24=0,"",'2026-21'!C24) | D24: =IF('2026-21'!D24=0,"",'2026-21'!D24) | E24: =IF('2026-21'!E24=0,"",'2026-21'!E24)
C25: =IF('2026-21'!C25=0,"",'2026-21'!C25) | D25: =IF('2026-21'!D25=0,"",'2026-21'!D25) | E25: =IF('2026-21'!E25=0,"",'2026-21'!E25)
C26: =IF('2026-21'!C26=0,"",'2026-21'!C26) | D26: =IF('2026-21'!D26=0,"",'2026-21'!D26) | E26: =IF('2026-21'!E26=0,"",'2026-21'!E26)
C27: Total Labor | E27: =SUM(E15:E26) -> 0 | G27: =IF(E27=100%,"","ERROR: TOTAL LABOR MUST BE 100%!!!") -> ERROR: TOTAL LABOR MUST BE 100%!!!
C28: I certify that the distribution of labor above represents the actual work performed during this reporting period.
C30: Employee Signature | Q30: Date
C32: Supervisor Signature | Q32: Date
C34: Budget Unit Head Signature | Q34: Date

Sheet 2026-23
C1: Payroll ID | E1: UNIVERSITY OF ALABAMA IN HUNTSVILLE
E2: Biweekly Labor Report
C3: 2026-23
C6: Name: | E6: ='2026-22'!E6:H6 -> 0 | I6: A#: | J6: ='2026-22'!J6:L6 -> 0 | M6: Position #: | O6: ='2026-22'!O6:P6 -> 0 | Q6: Title: | R6: ='2026-22'!R6:T6 -> 0
C8: Department: | E8: ='2026-22'!E8:H8 -> Earth System Science Center | I8: Pay Period: | K8: ='2026-22'!K8:L8+14 -> 46309 | M8: to | N8: ='2026-22'!N8:O8+14 -> 46322 | Q8: FTE: | R8: ='2026-22'!R8 -> 1
C10: Home Labor: | E10: ='2026-22'!E10:H10 -> 740001 | I10: Check Date: | L10: =N8+10 -> 46332
C14: 6 digit Org/Index | D14: Account Code | E14: % Distribution | G14: COMMENTS
C15: =IF('2026-22'!C15=0,"",'2026-22'!C15) | D15: =IF('2026-22'!D15=0,"",'2026-22'!D15) | E15: =IF('2026-22'!E15=0,"",'2026-22'!E15)
C16: =IF('2026-22'!C16=0,"",'2026-22'!C16) | D16: =IF('2026-22'!D16=0,"",'2026-22'!D16) | E16: =IF('2026-22'!E16=0,"",'2026-22'!E16)
C17: =IF('2026-22'!C17=0,"",'2026-22'!C17) | D17: =IF('2026-22'!D17=0,"",'2026-22'!D17) | E17: =IF('2026-22'!E17=0,"",'2026-22'!E17)
C18: =IF('2026-22'!C18=0,"",'2026-22'!C18) | D18: =IF('2026-22'!D18=0,"",'2026-22'!D18) | E18: =IF('2026-22'!E18=0,"",'2026-22'!E18)
C19: =IF('2026-22'!C19=0,"",'2026-22'!C19) | D19: =IF('2026-22'!D19=0,"",'2026-22'!D19) | E19: =IF('2026-22'!E19=0,"",'2026-22'!E19)
C20: =IF('2026-22'!C20=0,"",'2026-22'!C20) | D20: =IF('2026-22'!D20=0,"",'2026-22'!D20) | E20: =IF('2026-22'!E20=0,"",'2026-22'!E20)
C21: =IF('2026-22'!C21=0,"",'2026-22'!C21) | D21: =IF('2026-22'!D21=0,"",'2026-22'!D21) | E21: =IF('2026-22'!E21=0,"",'2026-22'!E21)
C22: =IF('2026-22'!C22=0,"",'2026-22'!C22) | D22: =IF('2026-22'!D22=0,"",'2026-22'!D22) | E22: =IF('2026-22'!E22=0,"",'2026-22'!E22)
C23: =IF('2026-22'!C23=0,"",'2026-22'!C23) | D23: =IF('2026-22'!D23=0,"",'2026-22'!D23) | E23: =IF('2026-22'!E23=0,"",'2026-22'!E23)
C24: =IF('2026-22'!C24=0,"",'2026-22'!C24) | D24: =IF('2026-22'!D24=0,"",'2026-22'!D24) | E24: =IF('2026-22'!E24=0,"",'2026-22'!E24)
C25: =IF('2026-22'!C25=0,"",'2026-22'!C25) | D25: =IF('2026-22'!D25=0,"",'2026-22'!D25) | E25: =IF('2026-22'!E25=0,"",'2026-22'!E25)
C26: =IF('2026-22'!C26=0,"",'2026-22'!C26) | D26: =IF('2026-22'!D26=0,"",'2026-22'!D26) | E26: =IF('2026-22'!E26=0,"",'2026-22'!E26)
C27: Total Labor | E27: =SUM(E15:E26) -> 0 | G27: =IF(E27=100%,"","ERROR: TOTAL LABOR MUST BE 100%!!!") -> ERROR: TOTAL LABOR MUST BE 100%!!!
C28: I certify that the distribution of labor above represents the actual work performed during this reporting period.
C30: Employee Signature | Q30: Date
C32: Supervisor Signature | Q32: Date
C34: Budget Unit Head Signature | Q34: Date

Sheet 2026-24
C1: Payroll ID | E1: UNIVERSITY OF ALABAMA IN HUNTSVILLE
E2: Biweekly Labor Report
C3: 2026-24
C6: Name: | E6: ='2026-23'!E6:H6 -> 0 | I6: A#: | J6: ='2026-23'!J6:L6 -> 0 | M6: Position #: | O6: ='2026-23'!O6:P6 -> 0 | Q6: Title: | R6: ='2026-23'!R6:T6 -> 0
C8: Department: | E8: ='2026-23'!E8:H8 -> Earth System Science Center | I8: Pay Period: | K8: ='2026-23'!K8:L8+14 -> 46323 | M8: to | N8: ='2026-23'!N8:O8+14 -> 46336 | Q8: FTE: | R8: ='2026-23'!R8 -> 1
C10: Home Labor: | E10: ='2026-23'!E10:H10 -> 740001 | I10: Check Date: | L10: =N8+10 -> 46346
C14: 6 digit Org/Index | D14: Account Code | E14: % Distribution | G14: COMMENTS
C15: =IF('2026-23'!C15=0,"",'2026-23'!C15) | D15: =IF('2026-23'!D15=0,"",'2026-23'!D15) | E15: =IF('2026-23'!E15=0,"",'2026-23'!E15)
C16: =IF('2026-23'!C16=0,"",'2026-23'!C16) | D16: =IF('2026-23'!D16=0,"",'2026-23'!D16) | E16: =IF('2026-23'!E16=0,"",'2026-23'!E16)
C17: =IF('2026-23'!C17=0,"",'2026-23'!C17) | D17: =IF('2026-23'!D17=0,"",'2026-23'!D17) | E17: =IF('2026-23'!E17=0,"",'2026-23'!E17)
C18: =IF('2026-23'!C18=0,"",'2026-23'!C18) | D18: =IF('2026-23'!D18=0,"",'2026-23'!D18) | E18: =IF('2026-23'!E18=0,"",'2026-23'!E18)
C19: =IF('2026-23'!C19=0,"",'2026-23'!C19) | D19: =IF('2026-23'!D19=0,"",'2026-23'!D19) | E19: =IF('2026-23'!E19=0,"",'2026-23'!E19)
